Workbook

Sheet IS
A1: Particulars | B1: 2021 | C1: =B1+1 -> 2022 | D1: =C1+1 -> 2023 | E1: =D1+1 -> 2024 | F1: =E1+1 -> 2025 | G1: =F1+1 -> 2026 | H1: =G1+1 -> 2027 | I1: =H1+1 -> 2028 | J1: =I1+1 -> 2029 | K1: =J1+1 -> 2030
A2: Revenue from operations | B2: 47028 | C2: 52466 | D2: 60580 | E2: 61896 | F2: 63121 | G2: =Assumption!G2 -> 65571.007 | H2: =Assumption!H2 -> 70238.271 | I2: =Assumption!I2 -> 75592.367 | J2: =Assumption!J2 -> 81845.858 | K2: =Assumption!K2 -> 89276.923
A3: Other income | B3: 410 | C3: 258 | D3: 512 | E3: 811 | F3: 1017 | G3: =Assumption!G3 -> 1118.7 | H3: =Assumption!H3 -> 1241.757 | I3: =Assumption!I3 -> 1390.7678 | J3: =Assumption!J3 -> 1571.5677 | K3: =Assumption!K3 -> 1791.5871
A4: Total Income | B4: =SUM(B2:B3) -> 47438 | C4: =SUM(C2:C3) -> 52724 | D4: =SUM(D2:D3) -> 61092 | E4: =SUM(E2:E3) -> 62707 | F4: =SUM(F2:F3) -> 64138 | G4: =SUM(G2:G3) -> 66689.707 | H4: =SUM(H2:H3) -> 71480.028 | I4: =SUM(I2:I3) -> 76983.135 | ... K4: =SUM(K2:K3) -> 91068.51
A5: Cost of materials consumed | B5: 15432 | C5: 16446 | D5: 20212 | E5: 19257 | F5: 19458 | G5: =Assumption!G4 -> 20912.303 | H5: =Assumption!H4 -> 22271.311 | I5: =Assumption!I4 -> 24023.761 | J5: =Assumption!J4 -> 25751.961 | K5: =Assumption!K4 -> 28152.94
A6: Purchases of stock-in-trade | B6: 7121 | C6: 9311 | D6: 11579 | E6: 10514 | F6: 11272 | G6: =Assumption!G5 -> 11389.247 | H6: =Assumption!H5 -> 12512.801 | I6: =Assumption!I5 -> 13476.912 | J6: =Assumption!J5 -> 14381.439 | K6: =Assumption!K5 -> 15791.599
A7: Changes in inventories of FG and WIP | B7: -405 | C7: -22 | D7: -75 | E7: -11 | F7: -153 | G7: =Assumption!G6 -> 0 | H7: =Assumption!H6 -> 0 | I7: =Assumption!I6 -> 0 | J7: =Assumption!J6 -> 0 | K7: =Assumption!K6 -> 0
A8: Employee benefits expenses | B8: 2358 | C8: 2545 | D8: 2854 | E8: 3009 | F8: 3077 | G8: =Assumption!G7 -> 3457.3172 | H8: =Assumption!H7 -> 3939.7858 | I8: =Assumption!I7 -> 4552.8165 | J8: =Assumption!J7 -> 5334.7627 | K8: =Assumption!K7 -> 6337.6981
A9: Finance costs | B9: 117 | C9: 106 | D9: 114 | E9: 334 | F9: 395 | G9: =Schedules!AE16 -> 398.85549 | H9: =Schedules!AF16 -> 402.71099 | I9: =Schedules!AG16 -> 406.56648 | J9: =Schedules!AH16 -> 410.42198 | K9: =Schedules!AI16 -> 414.27747
A10: Depreciation and amortisation expense | B10: 1074 | C10: 1091 | D10: 1137 | E10: 1216 | F10: 1355 | G10: =Schedules!S19 -> 1317.9938 | H10: =Schedules!T19 -> 1376.4159 | I10: =Schedules!U19 -> 1438.5245 | J10: =Schedules!V19 -> 1506.723 | K10: =Schedules!W19 -> 1572.2208
A11: Other expenses | B11: 10896 | C11: 11309 | D11: 11861 | E11: 14464 | F11: 14615 | G11: =Assumption!G8 -> 14440.372 | H11: =Assumption!H8 -> 15307.139 | I11: =Assumption!I8 -> 16509.985 | J11: =Assumption!J8 -> 18245.756 | K11: =Assumption!K8 -> 19710.333
A12: TOTAL EXPENSES | B12: =SUM(B5:B11) -> 36593 | C12: =SUM(C5:C11) -> 40786 | D12: =SUM(D5:D11) -> 47682 | E12: =SUM(E5:E11) -> 48783 | F12: =SUM(F5:F11) -> 50019 | G12: =SUM(G5:G11) -> 51916.088 | H12: =SUM(H5:H11) -> 55810.164 | I12: =SUM(I5:I11) -> 60408.566 | ... K12: =SUM(K5:K11) -> 71979.068
A13: Profit before exceptional items,share of equity accounted investee and tax | B13: =B4-B12 -> 10845 | C13: =C4-C12 -> 11938 | D13: =D4-D12 -> 13410 | E13: =E4-E12 -> 13924 | F13: =F4-F12 -> 14119 | G13: =G4-G12 -> 14773.619 | H13: =H4-H12 -> 15669.864 | I13: =I4-I12 -> 16574.569 | ... K13: =K4-K12 -> 19089.442
A14: Share of equity accounted investee and tax | B14: 0 | C14: 0 | D14: -1 | E14: -4 | F14: -8 | G14: =Assumption!G9 -> 0 | H14: =Assumption!H9 -> 0 | I14: =Assumption!I9 -> 0 | J14: =Assumption!J9 -> 0 | K14: =Assumption!K9 -> 0
A15: Profit before exceptional items and tax | B15: =B13+B14 -> 10845 | C15: =C13+C14 -> 11938 | D15: =D13+D14 -> 13409 | E15: =E13+E14 -> 13920 | F15: =F13+F14 -> 14111 | G15: =G13+G14 -> 14773.619 | H15: =H13+H14 -> 15669.864 | I15: =I13+I14 -> 16574.569 | ... K15: =K13+K14 -> 19089.442
A16: Exceptional items (net) | B16: -239 | C16: -44 | D16: -64 | E16: 6 | F16: 305 | G16: =Assumption!G10 -> 305 | H16: =Assumption!H10 -> 305 | I16: =Assumption!I10 -> 305 | J16: =Assumption!J10 -> 305 | K16: =Assumption!K10 -> 305
A17: Profit before tax | B17: =B15+B16 -> 10606 | C17: =C15+C16 -> 11894 | D17: =D15+D16 -> 13345 | E17: =E15+E16 -> 13926 | F17: =F15+F16 -> 14416 | G17: =G15+G16 -> 15078.619 | H17: =H15+H16 -> 15974.864 | I17: =I15+I16 -> 16879.569 | ... K17: =K15+K16 -> 19394.442
A18: Current tax | B18: -2520 | C18: -2840 | D18: -3001 | E18: -3521 | F18: -3620 | G18: =Assumption!G12 -> -3644.8051 | H18: =Assumption!H12 -> -3861.4455 | I18: =Assumption!I12 -> -4080.1309 | J18: =Assumption!J12 -> -4373.0458 | K18: =Assumption!K12 -> -4688.0261
A19: Deferred tax charge | B19: -86 | C19: -147 | D19: -200 | E19: -123 | F19: -124 | G19: =Assumption!G13 -> -124.84968 | H19: =Assumption!H13 -> -132.27051 | I19: =Assumption!I13 -> -139.76139 | J19: =Assumption!J13 -> -149.79494 | K19: =Assumption!K13 -> -160.58432
A20: Profit after tax | B20: =B17+B18+B19 -> 8000 | C20: =C17+C18+C19 -> 8907 | D20: =D17+D18+D19 -> 10144 | E20: =E17+E18+E19 -> 10282 | F20: =F17+F18+F19 -> 10672 | G20: =G17+G18+G19 -> 11308.964 | H20: =H17+H18+H19 -> 11981.148 | I20: =I17+I18+I19 -> 12659.677 | ... K20: =K17+K18+K19 -> 14545.831
A21: Dividend Paid | B21: 9517.5 | C21: 7990 | D21: 9165 | E21: 9870 | F21: 12455 | G21: =Assumption!G96 -> 9400 | H21: =Assumption!H96 -> 8812.5 | I21: =Assumption!I96 -> 8812.5 | J21: =Assumption!J96 -> 8812.5 | K21: =Assumption!K96 -> 8812.5
A22: Retained Earnings | B22: =B20-B21 -> -1517.5 | C22: =C20-C21 -> 917 | D22: =D20-D21 -> 979 | E22: =E20-E21 -> 412 | F22: =F20-F21 -> -1783 | G22: =G20-G21 -> 1908.9642 | H22: =H20-H21 -> 3168.6481 | I22: =I20-I21 -> 3847.1769 | ... K22: =K20-K21 -> 5733.3313

Sheet BS
A1: Particulars | B1: 2021 | C1: =B1+1 -> 2022 | D1: =C1+1 -> 2023 | E1: =D1+1 -> 2024 | F1: =E1+1 -> 2025 | G1: =F1+1 -> 2026 | H1: =G1+1 -> 2027 | I1: =H1+1 -> 2028 | J1: =I1+1 -> 2029 | K1: =J1+1 -> 2030
A2: Assets
A3: Non-current assets
A4: Property, plant and equipment | B4: 6116 | C4: 6169 | D4: 6949 | E4: 8031 | F4: 8625 | G4: =Schedules!S2 -> 7980.0509 | H4: =Schedules!T2 -> 7265.5322 | I4: =Schedules!U2 -> 6510.6562 | J4: =Schedules!V2 -> 5710.7641 | K4: =Schedules!W2 -> 4870.5769
A5: Capital work-in-progress | B5: 745 | C5: 1313 | D5: 1132 | E5: 1025 | F5: 1009 | G5: =Assumption!G74 -> 1009 | H5: =Assumption!H74 -> 1009 | I5: =Assumption!I74 -> 1009 | J5: =Assumption!J74 -> 1009 | K5: =Assumption!K74 -> 1009
A6: Goodwill | B6: 17397 | C6: 17397 | D6: 17466 | E6: 17466 | F6: 17466 | G6: =Assumption!G75 -> 17466 | H6: =Assumption!H75 -> 17466 | I6: =Assumption!I75 -> 17466 | J6: =Assumption!J75 -> 17466 | K6: =Assumption!K75 -> 17466
A7: Other intangible assets | B7: 27930 | C7: 27907 | D7: 28263 | E7: 28247 | F7: 28243 | G7: =Schedules!S5 -> 29424.955 | H7: =Schedules!T5 -> 30581.052 | I7: =Schedules!U5 -> 31773.819 | J7: =Schedules!V5 -> 33005.513 | K7: =Schedules!W5 -> 34280.202
A8: Investments accounted for using the equity method | B8: 0 | C8: 0 | D8: 69 | E8: 65 | F8: 57 | G8: =Assumption!G76 -> 57 | H8: =Assumption!H76 -> 57 | I8: =Assumption!I76 -> 57 | J8: =Assumption!J76 -> 57 | K8: =Assumption!K76 -> 57
A9: Investments | B9: 2 | C9: 2 | D9: 2 | E9: 2 | F9: 2 | G9: =Assumption!G77 -> 2 | H9: =Assumption!H77 -> 2 | I9: =Assumption!I77 -> 2 | J9: =Assumption!J77 -> 2 | K9: =Assumption!K77 -> 2
A10: Loans | B10: 111 | C10: 115 | D10: 98 | E10: 102 | F10: 87 | G10: =Assumption!G78 -> 87 | H10: =Assumption!H78 -> 87 | I10: =Assumption!I78 -> 87 | J10: =Assumption!J78 -> 87 | K10: =Assumption!K78 -> 87
A11: Other financial assets | B11: 757 | C11: 729 | D11: 725 | E11: 760 | F11: 763 | G11: =Assumption!G79 -> 763 | H11: =Assumption!H79 -> 763 | I11: =Assumption!I79 -> 763 | J11: =Assumption!J79 -> 763 | K11: =Assumption!K79 -> 763
A12: Deferred tax assets (net) | B12: 17 | C12: 11 | D12: 10 | E12: 10 | F12: 17 | G12: =Assumption!G80 -> 17 | H12: =Assumption!H80 -> 17 | I12: =Assumption!I80 -> 17 | J12: =Assumption!J80 -> 17 | K12: =Assumption!K80 -> 17
A13: Non-current tax assets (net) | B13: 1246 | C13: 1158 | D13: 1164 | E13: 1175 | F13: 1199 | G13: =Assumption!G81 -> 1199 | H13: =Assumption!H81 -> 1199 | I13: =Assumption!I81 -> 1199 | J13: =Assumption!J81 -> 1199 | K13: =Assumption!K81 -> 1199
A14: Other non-current assets | B14: 219 | C14: 194 | D14: 211 | E14: 292 | F14: 360 | G14: =Assumption!G82 -> 360 | H14: =Assumption!H82 -> 360 | I14: =Assumption!I82 -> 360 | J14: =Assumption!J82 -> 360 | K14: =Assumption!K82 -> 360
A15: Current Assets
A16: Inventories | B16: 3579 | C16: 4096 | D16: 4251 | E16: 4022 | F16: 4415 | G16: =Schedules!G3 -> 4711.5375 | H16: =Schedules!H3 -> 4987.2017 | I16: =Schedules!I3 -> 5260.5437 | J16: =Schedules!J3 -> 5686.2239 | K16: =Schedules!K3 -> 6282.7524
A17: Investments | B17: 2707 | C17: 3519 | D17: 2811 | E17: 4558 | F17: 3751 | G17: =Schedules!G4 -> 3988.0302 | H17: =Schedules!H4 -> 4317.6685 | I17: =Schedules!I4 -> 4562.1266 | J17: =Schedules!J4 -> 5167.889 | K17: =Schedules!K4 -> 5449.6548
A18: Trade receivables | B18: 1758 | C18: 2236 | D18: 3079 | E18: 2997 | F18: 3819 | G18: =Schedules!G5 -> 3144.1061 | H18: =Schedules!H5 -> 3516.3504 | I18: =Schedules!I5 -> 3896.9519 | J18: =Schedules!J5 -> 4231.2307 | K18: =Schedules!K5 -> 4673.9217
A19: Cash and cash equivalents | B19: 1842 | C19: 1147 | D19: 714 | E19: 825 | F19: 6071 | G19: =CF!B20 -> 3038.6269 | H19: =CF!C20 -> 5112.151 | I19: =CF!D20 -> 8224.7422 | J19: =CF!E20 -> 12173.95 | K19: =CF!F20 -> 17179.494
A20: Bank balances other than cash equivalents | B20: 2629 | C20: 2699 | D20: 3964 | E20: 6734 | F20: 1483 | G20: =Schedules!G6 -> 3952.2251 | H20: =Schedules!H6 -> 4425.9733 | I20: =Schedules!I6 -> 4970.457 | J20: =Schedules!J6 -> 5605.8807 | K20: =Schedules!K6 -> 6359.4521
A21: Loans | B21: 34 | C21: 35 | D21: 36 | E21: 38 | F21: 46 | G21: =Schedules!G7 -> 43.631209 | H21: =Schedules!H7 -> 45.928107 | I21: =Schedules!I7 -> 49.229403 | J21: =Schedules!J7 -> 54.234904 | K21: =Schedules!K7 -> 60.02888
A22: Other financial assets (current) | B22: 1154 | C22: 1089 | D22: 1386 | E22: 1425 | F22: 1488 | G22: =Schedules!G8 -> 1505.1165 | H22: =Schedules!H8 -> 1589.9892 | I22: =Schedules!I8 -> 1739.6248 | J22: =Schedules!J8 -> 1885.7379 | K22: =Schedules!K8 -> 2057.2651
A23: Other current assets | B23: 497 | C23: 688 | D23: 745 | E23: 713 | F23: 955 | G23: =Schedules!G9 -> 821.31895 | H23: =Schedules!H9 -> 907.27728 | I23: =Schedules!I9 -> 973.47185 | J23: =Schedules!J9 -> 1063.4999 | K23: =Schedules!K9 -> 1186.3885
A24: Assets held for sale | B24: 17 | C24: 13 | D24: 12 | E24: 12 | F24: 23 | G24: =Schedules!G10 -> 17.908814 | H24: =Schedules!H10 -> 17.942208 | I24: =Schedules!I10 -> 19.425832 | J24: =Schedules!J10 -> 21.996945 | K24: =Schedules!K10 -> 25.331259
A25: Total Assets | B25: =SUM(B16:B24,B4:B14) -> 68757 | C25: =SUM(C16:C24,C4:C14) -> 70517 | D25: =SUM(D16:D24,D4:D14) -> 73087 | E25: =SUM(E16:E24,E4:E14) -> 78499 | F25: =SUM(F16:F24,F4:F14) -> 79879 | G25: =SUM(G16:G24,G4:G14) -> 79587.507 | H25: =SUM(H16:H24,H4:H14) -> 83727.066 | I25: =SUM(I16:I24,I4:I14) -> 88941.049 | ... K25: =SUM(K16:K24,K4:K14) -> 103385.07
A26: Equity And Liability
A27: Equity
A28: Equity share capital | B28: 235 | C28: 235 | D28: 235 | E28: 235 | F28: 235 | G28: =Assumption!G90 -> 235 | H28: =Assumption!H90 -> 235 | I28: =Assumption!I90 -> 235 | J28: =Assumption!J90 -> 235 | K28: =Assumption!K90 -> 235
A29: Other equity | B29: 47439 | C29: 48826 | D29: 50069 | E29: 50983 | F29: 49167 | G29: =Assumption!G91 -> 51075.964 | H29: =Assumption!H91 -> 54244.612 | I29: =Assumption!I91 -> 58091.789 | J29: =Assumption!J91 -> 62847.811 | K29: =Assumption!K91 -> 68581.143
A30: Non-controlling interests | B30: 20 | C30: 26 | D30: 218 | E30: 205 | F30: 207 | G30: =Assumption!G92 -> 207 | H30: =Assumption!H92 -> 207 | I30: =Assumption!I92 -> 207 | J30: =Assumption!J92 -> 207 | K30: =Assumption!K92 -> 207
A31: Liabilities
A32: Non-current liabilities
A33: Lease Liabilities | B33: 731 | C33: 741 | D33: 807 | E33: 1106 | F33: 1243 | G33: =Schedules!AE6 -> 1280.7353 | H33: =Schedules!AF6 -> 1318.4706 | I33: =Schedules!AG6 -> 1356.2058 | J33: =Schedules!AH6 -> 1393.9411 | K33: =Schedules!AI6 -> 1431.6764
A34: Other financial liabilities (non-current) | B34: 296 | C34: 357 | D34: 860 | E34: 718 | F34: 680 | G34: =Assumption!G83 -> 680 | H34: =Assumption!H83 -> 680 | I34: =Assumption!I83 -> 680 | J34: =Assumption!J83 -> 680 | K34: =Assumption!K83 -> 680
A35: Provisions (non-current) | B35: 1578 | C35: 1580 | D35: 1363 | E35: 1576 | F35: 1528 | G35: =Assumption!G84 -> 1528 | H35: =Assumption!H84 -> 1528 | I35: =Assumption!I84 -> 1528 | J35: =Assumption!J84 -> 1528 | K35: =Assumption!K84 -> 1528
A36: Deferred tax liabilities (net) | B36: 5988 | C36: 6141 | D36: 6421 | E36: 6557 | F36: 6685 | G36: =Assumption!G85 -> 6685 | H36: =Assumption!H85 -> 6685 | I36: =Assumption!I85 -> 6685 | J36: =Assumption!J85 -> 6685 | K36: =Assumption!K85 -> 6685
A37: Non-current tax liabilities (net) | B37: 1367 | C37: 1331 | D37: 1086 | E37: 4243 | F37: 3598 | G37: =Assumption!G86 -> 3598 | H37: =Assumption!H86 -> 3598 | I37: =Assumption!I86 -> 3598 | J37: =Assumption!J86 -> 3598 | K37: =Assumption!K86 -> 3598
A38: Current Liabilities
A39: Borrowings | B39: 0 | C39: 0 | D39: 98 | E39: 13 | F39: 1 | G39: =Schedules!AE3 -> 0 | H39: =Schedules!AF3 -> 0 | I39: =Schedules!AG3 -> 0 | J39: =Schedules!AH3 -> 0 | K39: =Schedules!AI3 -> 0
A40: Lease Liabilities | B40: 278 | C40: 302 | D40: 314 | E40: 365 | F40: 404 | G40: =Schedules!AE7 -> 416.26472 | H40: =Schedules!AF7 -> 428.52945 | I40: =Schedules!AG7 -> 440.79417 | J40: =Schedules!AH7 -> 453.05889 | K40: =Schedules!AI7 -> 465.32362
...

Sheet CF
A1: Cash Flow | B1: =2025+1 -> 2026 | C1: =B1+1 -> 2027 | D1: =C1+1 -> 2028 | E1: =D1+1 -> 2029 | F1: =E1+1 -> 2030
A2: Net Profit | B2: =IS!G20 -> 11308.964 | C2: =IS!H20 -> 11981.148 | D2: =IS!I20 -> 12659.677 | E2: =IS!J20 -> 13568.522 | F2: =IS!K20 -> 14545.831
A3: Add Finance Costs | B3: =IS!G9 -> 398.85549 | C3: =IS!H9 -> 402.71099 | D3: =IS!I9 -> 406.56648 | E3: =IS!J9 -> 410.42198 | F3: =IS!K9 -> 414.27747
A4: Add Depreciation | B4: =IS!G10 -> 1317.9938 | C4: =IS!H10 -> 1376.4159 | D4: =IS!I10 -> 1438.5245 | E4: =IS!J10 -> 1506.723 | F4: =IS!K10 -> 1572.2208
A5: Less Change in Net Working Capital | B5: =-Schedules!G19 -> -4454.3311 | C5: =-Schedules!H19 -> -703.54614 | D5: =-Schedules!I19 -> -346.69432 | E5: =-Schedules!J19 -> -425.01257 | F5: =-Schedules!K19 -> -343.28522
A6: Cash Flow from Operating Activities | B6: =SUM(B2:B5) -> 8571.4824 | C6: =SUM(C2:C5) -> 13056.729 | D6: =SUM(D2:D5) -> 14158.074 | E6: =SUM(E2:E5) -> 15060.654 | F6: =SUM(F2:F5) -> 16189.044
A8: Change in Investments | B8: =-(SUM(Assumption!G74:G86)-SUM(Assumption!F74:F86)) -> 0 | C8: =-(SUM(Assumption!H74:H86)-SUM(Assumption!G74:G86)) -> 0 | D8: =-(SUM(Assumption!I74:I86)-SUM(Assumption!H74:H86)) -> 0 | E8: =-(SUM(Assumption!J74:J86)-SUM(Assumption!I74:I86)) -> 0 | F8: =-(SUM(Assumption!K74:K86)-SUM(Assumption!J74:J86)) -> 0
A9: Capital Expenditure | B9: =-Schedules!S22 -> -1855 | C9: =-Schedules!T22 -> -1817.9938 | D9: =-Schedules!U22 -> -1876.4159 | E9: =-Schedules!V22 -> -1938.5245 | F9: =-Schedules!W22 -> -2006.723
A10: Cash Flow from Investing Activities | B10: =SUM(B8:B9) -> -1855 | C10: =SUM(C8:C9) -> -1817.9938 | D10: =SUM(D8:D9) -> -1876.4159 | E10: =SUM(E8:E9) -> -1938.5245 | F10: =SUM(F8:F9) -> -2006.723
A12: Changes to Equity | B12: =(Assumption!G90+Assumption!G92)-(Assumption!F90+Assumption!F92) -> 0 | C12: =(Assumption!H90+Assumption!H92)-(Assumption!G90+Assumption!G92) -> 0 | D12: =(Assumption!I90+Assumption!I92)-(Assumption!H90+Assumption!H92) -> 0 | E12: =(Assumption!J90+Assumption!J92)-(Assumption!I90+Assumption!I92) -> 0 | F12: =(Assumption!K90+Assumption!K92)-(Assumption!J90+Assumption!J92) -> 0
A13: Net Loans Raised for the long term | B13: =Schedules!AE21+Schedules!AE22 -> 50 | C13: =Schedules!AF21+Schedules!AF22 -> 50 | D13: =Schedules!AG21+Schedules!AG22 -> 50 | E13: =Schedules!AH21+Schedules!AH22 -> 50 | F13: =Schedules!AI21+Schedules!AI22 -> 50
A14: Finance Costs Paid | B14: =-IS!G9 -> -398.85549 | C14: =-IS!H9 -> -402.71099 | D14: =-IS!I9 -> -406.56648 | E14: =-IS!J9 -> -410.42198 | F14: =-IS!K9 -> -414.27747
A15: Dividend Paid | B15: =-IS!G21 -> -9400 | C15: =-IS!H21 -> -8812.5 | D15: =-IS!I21 -> -8812.5 | E15: =-IS!J21 -> -8812.5 | F15: =-IS!K21 -> -8812.5
A16: Cash Flow from Financing Activities | B16: =SUM(B12:B15) -> -9748.8555 | C16: =SUM(C12:C15) -> -9165.211 | D16: =SUM(D12:D15) -> -9169.0665 | E16: =SUM(E12:E15) -> -9172.922 | F16: =SUM(F12:F15) -> -9176.7775
A18: Total Cash Flow | B18: =B6+B10+B16 -> -3032.3731 | C18: =C6+C10+C16 -> 2073.5241 | D18: =D6+D10+D16 -> 3112.5912 | E18: =E6+E10+E16 -> 3949.208 | F18: =F6+F10+F16 -> 5005.5439
A19: Beginning Cash Balance | B19: =BS!F19 -> 6071 | C19: =B20 -> 3038.6269 | D19: =C20 -> 5112.151 | E19: =D20 -> 8224.7422 | F19: =E20 -> 12173.95
A20: Closing Cash Balance in Balance Sheet | B20: =B18+B19 -> 3038.6269 | C20: =C18+C19 -> 5112.151 | D20: =D18+D19 -> 8224.7422 | E20: =E18+E19 -> 12173.95 | F20: =F18+F19 -> 17179.494

Sheet Schedules
A1: Working Capital Schedule | B1: 2021 | C1: =B1+1 -> 2022 | D1: =C1+1 -> 2023 | E1: =D1+1 -> 2024 | F1: =E1+1 -> 2025 | G1: =F1+1 -> 2026 | H1: =G1+1 -> 2027 | I1: =H1+1 -> 2028 | J1: =I1+1 -> 2029 | K1: =J1+1 -> 2030 | M1: Capex Schedule | N1: 2021 | O1: =N1+1 -> 2022 | P1: =O1+1 -> 2023 | Q1: =P1+1 -> 2024 | R1: =Q1+1 -> 2025 | S1: =R1+1 -> 2026 | T1: =S1+1 -> 2027 | U1: =T1+1 -> 2028 | V1: =U1+1 -> 2029 | W1: =V1+1 -> 2030 | Y1: Debt Schedule | Z1: 2021 | AA1: =Z1+1 -> 2022 | AB1: =AA1+1 -> 2023 | AC1: =AB1+1 -> 2024 | AD1: =AC1+1 -> 2025 | AE1: =AD1+1 -> 2026 | AF1: =AE1+1 -> 2027 | AG1: =AF1+1 -> 2028 | AH1: =AG1+1 -> 2029 | AI1: =AH1+1 -> 2030
A2: Current Assets Other than cash | M2: Property, Plant & Equipment | N2: =BS!B4 -> 6116 | O2: =BS!C4 -> 6169 | P2: =BS!D4 -> 6949 | Q2: =BS!E4 -> 8031 | R2: =BS!F4 -> 8625 | S2: =S3+S4 -> 7980.0509 | T2: =T3+T4 -> 7265.5322 | U2: =U3+U4 -> 6510.6562 | V2: =V3+V4 -> 5710.7641 | W2: =W3+W4 -> 4870.5769 | Y2: Long term Borrowings | Z2: 0 | AA2: 0 | AB2: 0 | AC2: 0 | AD2: 0 | AE2: =AD2 -> 0 | AF2: =AE2 -> 0 | AG2: =AF2 -> 0 | AH2: =AG2 -> 0 | AI2: =AH2 -> 0
A3: Inventories | B3: =BS!B16 -> 3579 | C3: =BS!C16 -> 4096 | D3: =BS!D16 -> 4251 | E3: =BS!E16 -> 4022 | F3: =BS!F16 -> 4415 | G3: =G22*IS!G$2/365 -> 4711.5375 | H3: =H22*IS!H$2/365 -> 4987.2017 | I3: =I22*IS!I$2/365 -> 5260.5437 | J3: =J22*IS!J$2/365 -> 5686.2239 | K3: =K22*IS!K$2/365 -> 6282.7524 | M3: Owned | N3: 5067 | O3: 5101 | P3: 5767 | Q3: 6517 | R3: 6941 | S3: =S16 -> 6417.4909 | T3: =T16 -> 5837.7204 | U3: =U16 -> 5225.2424 | V3: =V16 -> 4576.2838 | W3: =W16 -> 3894.6596 | Y3: Short Term Borrowing | Z3: =BS!B39 -> 0 | AA3: =BS!C39 -> 0 | AB3: =BS!D39 -> 98 | AC3: =BS!E39 -> 13 | AD3: =BS!F39 -> 1 | AE3: =0 -> 0 | AF3: =0 -> 0 | AG3: =0 -> 0 | AH3: =0 -> 0 | AI3: =0 -> 0
A4: Investments | B4: =BS!B17 -> 2707 | C4: =BS!C17 -> 3519 | D4: =BS!D17 -> 2811 | E4: =BS!E17 -> 4558 | F4: =BS!F17 -> 3751 | G4: =G23*IS!G$2/365 -> 3988.0302 | H4: =H23*IS!H$2/365 -> 4317.6685 | I4: =I23*IS!I$2/365 -> 4562.1266 | J4: =J23*IS!J$2/365 -> 5167.889 | K4: =K23*IS!K$2/365 -> 5449.6548 | M4: Leased(Right of Use Assets) | N4: 1049 | O4: 1068 | P4: 1182 | Q4: 1514 | R4: 1684 | S4: =S17 -> 1562.5601 | T4: =T17 -> 1427.8119 | U4: =U17 -> 1285.4138 | V4: =V17 -> 1134.4803 | W4: =W17 -> 975.91737 | Y4: Total Borrowings | Z4: =Z2+Z3 -> 0 | AA4: =AA2+AA3 -> 0 | AB4: =AB2+AB3 -> 98 | AC4: =AC2+AC3 -> 13 | AD4: =AD2+AD3 -> 1 | AE4: 0 | AF4: =AE4+AF21 -> 0 | AG4: =AF4+AG21 -> 0 | AH4: =AG4+AH21 -> 0 | AI4: =AH4+AI21 -> 0
A5: Trade receivables | B5: =BS!B18 -> 1758 | C5: =BS!C18 -> 2236 | D5: =BS!D18 -> 3079 | E5: =BS!E18 -> 2997 | F5: =BS!F18 -> 3819 | G5: =G24*IS!G$2/365 -> 3144.1061 | H5: =H24*IS!H$2/365 -> 3516.3504 | I5: =I24*IS!I$2/365 -> 3896.9519 | J5: =J24*IS!J$2/365 -> 4231.2307 | K5: =K24*IS!K$2/365 -> 4673.9217 | M5: Other Intangible Assets | N5: =BS!B7 -> 27930 | O5: =BS!C7 -> 27907 | P5: =BS!D7 -> 28263 | Q5: =BS!E7 -> 28247 | R5: =BS!F7 -> 28243 | S5: =S18 -> 29424.955 | T5: =T18 -> 30581.052 | U5: =U18 -> 31773.819 | V5: =V18 -> 33005.513 | W5: =W18 -> 34280.202
A6: Bank balances other than cash equivalents | B6: =BS!B20 -> 2629 | C6: =BS!C20 -> 2699 | D6: =BS!D20 -> 3964 | E6: =BS!E20 -> 6734 | F6: =BS!F20 -> 1483 | G6: =G25*IS!G$2/365 -> 3952.2251 | H6: =H25*IS!H$2/365 -> 4425.9733 | I6: =I25*IS!I$2/365 -> 4970.457 | J6: =J25*IS!J$2/365 -> 5605.8807 | K6: =K25*IS!K$2/365 -> 6359.4521 | Y6: Long Term Lease | Z6: =BS!B33 -> 731 | AA6: =BS!C33 -> 741 | AB6: =BS!D33 -> 807 | AC6: =BS!E33 -> 1106 | AD6: =BS!F33 -> 1243 | AE6: =AD$6/AD$8*AE$8 -> 1280.7353 | AF6: =AE$6/AE$8*AF$8 -> 1318.4706 | AG6: =AF$6/AF$8*AG$8 -> 1356.2058 | AH6: =AG$6/AG$8*AH$8 -> 1393.9411 | AI6: =AH$6/AH$8*AI$8 -> 1431.6764
A7: Loans | B7: =BS!B21 -> 34 | C7: =BS!C21 -> 35 | D7: =BS!D21 -> 36 | E7: =BS!E21 -> 38 | F7: =BS!F21 -> 46 | G7: =G26*IS!G$2/365 -> 43.631209 | H7: =H26*IS!H$2/365 -> 45.928107 | I7: =I26*IS!I$2/365 -> 49.229403 | J7: =J26*IS!J$2/365 -> 54.234904 | K7: =K26*IS!K$2/365 -> 60.02888 | M7: Gross Long Term Assets: | N7: =SUM(N8:N10) -> 37527 | O7: =SUM(O8:O10) -> 38181 | P7: =SUM(P8:P10) -> 40098 | Q7: =SUM(Q8:Q10) -> 41782 | R7: =SUM(R8:R10) -> 43298 | S7: =R7+S22 -> 45153 | T7: =S7+T22 -> 46970.994 | U7: =T7+U22 -> 48847.41 | V7: =U7+V22 -> 50785.934 | W7: =V7+W22 -> 52792.657 | Y7: Short Term Lease | Z7: =BS!B40 -> 278 | AA7: =BS!C40 -> 302 | AB7: =BS!D40 -> 314 | AC7: =BS!E40 -> 365 | AD7: =BS!F40 -> 404 | AE7: =AD$7/AD$8*AE$8 -> 416.26472 | AF7: =AE$7/AE$8*AF$8 -> 428.52945 | AG7: =AF$7/AF$8*AG$8 -> 440.79417 | AH7: =AG$7/AG$8*AH$8 -> 453.05889 | AI7: =AH$7/AH$8*AI$8 -> 465.32362
A8: Other financial assets (current) | B8: =BS!B22 -> 1154 | C8: =BS!C22 -> 1089 | D8: =BS!D22 -> 1386 | E8: =BS!E22 -> 1425 | F8: =BS!F22 -> 1488 | G8: =G27*IS!G$2/365 -> 1505.1165 | H8: =H27*IS!H$2/365 -> 1589.9892 | I8: =I27*IS!I$2/365 -> 1739.6248 | J8: =J27*IS!J$2/365 -> 1885.7379 | K8: =K27*IS!K$2/365 -> 2057.2651 | M8: Owned | N8: 7896 | O8: 8402 | P8: 9663 | Q8: 10999 | R8: 12004 | S8: =$R8/$R$7*S$7 -> 12518.283 | T8: =$R8/$R$7*T$7 -> 13022.306 | U8: =$R8/$R$7*U$7 -> 13542.526 | V8: =$R8/$R$7*V$7 -> 14079.966 | W8: =$R8/$R$7*W$7 -> 14636.312 | Y8: Total Lease | Z8: =Z6+Z7 -> 1009 | AA8: =AA6+AA7 -> 1043 | AB8: =AB6+AB7 -> 1121 | AC8: =AC6+AC7 -> 1471 | AD8: =AD6+AD7 -> 1647 | AE8: =AD8+AE22 -> 1697 | AF8: =AE8+AF22 -> 1747 | AG8: =AF8+AG22 -> 1797 | AH8: =AG8+AH22 -> 1847 | AI8: =AH8+AI22 -> 1897
A9: Other current assets | B9: =BS!B23 -> 497 | C9: =BS!C23 -> 688 | D9: =BS!D23 -> 745 | E9: =BS!E23 -> 713 | F9: =BS!F23 -> 955 | G9: =G28*IS!G$2/365 -> 821.31895 | H9: =H28*IS!H$2/365 -> 907.27728 | I9: =I28*IS!I$2/365 -> 973.47185 | J9: =J28*IS!J$2/365 -> 1063.4999 | K9: =K28*IS!K$2/365 -> 1186.3885 | M9: Leased(Right of Use Assets) | N9: 1611 | O9: 1762 | P9: 2038 | Q9: 2377 | R9: 2878 | S9: =$R9/$R$7*S$7 -> 3001.3011 | T9: =$R9/$R$7*T$7 -> 3122.1424 | U9: =$R9/$R$7*U$7 -> 3246.8669 | V9: =$R9/$R$7*V$7 -> 3375.7199 | W9: =$R9/$R$7*W$7 -> 3509.1059
A10: Assets held for sale | B10: =BS!B24 -> 17 | C10: =BS!C24 -> 13 | D10: =BS!D24 -> 12 | E10: =BS!E24 -> 12 | F10: =BS!F24 -> 23 | G10: =G29*IS!G$2/365 -> 17.908814 | H10: =H29*IS!H$2/365 -> 17.942208 | I10: =I29*IS!I$2/365 -> 19.425832 | J10: =J29*IS!J$2/365 -> 21.996945 | K10: =K29*IS!K$2/365 -> 25.331259 | M10: Other intangible assets | N10: 28020 | O10: 28017 | P10: 28397 | Q10: 28406 | R10: 28416 | S10: =$R10/$R$7*S$7 -> 29633.416 | T10: =$R10/$R$7*T$7 -> 30826.545 | U10: =$R10/$R$7*U$7 -> 32058.016 | V10: =$R10/$R$7*V$7 -> 33330.249 | W10: =$R10/$R$7*W$7 -> 34647.239 | Y10: Interest expense on Loan on bank overdraft, security deposit and others | Z10: 2 | AA10: 2 | AB10: 4 | AC10: 4 | AD10: 3 | AE10: =AD10 -> 3 | AF10: =AE10 -> 3 | AG10: =AF10 -> 3 | AH10: =AG10 -> 3 | AI10: =AH10 -> 3
A11: Current Liabilities | M11: Accumulated Depreciation: | N11: =SUM(N12:N14) -> 3481 | O11: =SUM(O12:O14) -> 4105 | P11: =SUM(P12:P14) -> 4886 | Q11: =SUM(Q12:Q14) -> 5504 | R11: =SUM(R12:R14) -> 6430 | S11: =R11+S19 -> 7747.9938 | T11: =S11+T19 -> 9124.4097 | U11: =T11+U19 -> 10562.934 | V11: =U11+V19 -> 12069.657 | W11: =V11+W19 -> 13641.878 | Y11: Net interest on the net defined benefit liability | Z11: 13 | AA11: 15 | AB11: 16 | AC11: 24 | AD11: 23 | AE11: =AD11 -> 23 | AF11: =AE11 -> 23 | AG11: =AF11 -> 23 | AH11: =AG11 -> 23 | AI11: =AH11 -> 23
A12: Trade payables - micro & small enterprises | B12: =BS!B41 -> 67 | C12: =BS!C41 -> 60 | D12: =BS!D41 -> 100 | E12: =BS!E41 -> 250 | F12: =BS!F41 -> 263 | G12: =G32*IS!G$2/365 -> 162.93903 | H12: =H32*IS!H$2/365 -> 189.43074 | I12: =I32*IS!I$2/365 -> 227.35526 | J12: =J32*IS!J$2/365 -> 268.37552 | K12: =K32*IS!K$2/365 -> 279.17221 | M12: Owned | N12: 2829 | O12: 3301 | P12: 3896 | Q12: 4482 | R12: 5063 | S12: =$R12/$R$11*S$11 -> 6100.792 | T12: =$R12/$R$11*T$11 -> 7184.5857 | U12: =$R12/$R$11*U$11 -> 8317.284 | V12: =$R12/$R$11*V$11 -> 9503.6819 | W12: =$R12/$R$11*W$11 -> 10741.653 | Y12: Unwinding of discount on provisions and liabilities | Z12: 6 | AA12: 3 | AB12: 2 | AC12: 20 | AD12: 16 | AE12: =AD12 -> 16 | AF12: =AE12 -> 16 | AG12: =AF12 -> 16 | AH12: =AG12 -> 16 | AI12: =AH12 -> 16
A13: Trade payables - others | B13: =BS!B42 -> 8735 | C13: =BS!C42 -> 9008 | D13: =BS!D42 -> 9474 | E13: =BS!E42 -> 10236 | F13: =BS!F42 -> 11052 | G13: =G33*IS!G$2/365 -> 11203.295 | H13: =H33*IS!H$2/365 -> 11791.661 | I13: =I33*IS!I$2/365 -> 12632.891 | J13: =J33*IS!J$2/365 -> 13853.613 | K13: =K33*IS!K$2/365 -> 15180.896 | M13: Leased(Right of Use Assets) | N13: 562 | O13: 694 | P13: 856 | Q13: 863 | R13: 1194 | S13: =$R13/$R$11*S$11 -> 1438.741 | T13: =$R13/$R$11*T$11 -> 1694.3305 | U13: =$R13/$R$11*U$11 -> 1961.4531 | V13: =$R13/$R$11*V$11 -> 2241.2396 | W13: =$R13/$R$11*W$11 -> 2533.1885 | Y13: Unwinding of discount on employee and ex-employee related liabilities | Z13: 6 | AA13: 4 | AB13: 8 | AC13: 9 | AD13: 11 | AE13: =AD13 -> 11 | AF13: =AE13 -> 11 | AG13: =AF13 -> 11 | AH13: =AG13 -> 11 | AI13: =AH13 -> 11
A14: Other financial liabilities | B14: =BS!B43 -> 928 | C14: =BS!C43 -> 899 | D14: =BS!D43 -> 889 | E14: =BS!E43 -> 865 | F14: =BS!F43 -> 1280 | G14: =G34*IS!G$2/365 -> 1125.1488 | H14: =H34*IS!H$2/365 -> 1169.0813 | I14: =I34*IS!I$2/365 -> 1250.7834 | J14: =J34*IS!J$2/365 -> 1384.8931 | K14: =K34*IS!K$2/365 -> 1563.2288 | M14: Other intangible assets | N14: 90 | O14: 110 | P14: 134 | Q14: 159 | R14: 173 | S14: =$R14/$R$11*S$11 -> 208.4608 | T14: =$R14/$R$11*T$11 -> 245.49345 | U14: =$R14/$R$11*U$11 -> 284.19714 | V14: =$R14/$R$11*V$11 -> 324.73572 | W14: =$R14/$R$11*W$11 -> 367.03653 | Y14: Interest on Lease Liabilities | Z14: 86 | AA14: 80 | AB14: 84 | AC14: 106 | AD14: 127 | AE14: =AE19*AE8 -> 130.85549 | AF14: =AF19*AF8 -> 134.71099 | AG14: =AG19*AG8 -> 138.56648 | AH14: =AH19*AH8 -> 142.42198 | AI14: =AI19*AI8 -> 146.27747
A15: Other current liabilities | B15: =BS!B44 -> 588 | C15: =BS!C44 -> 665 | D15: =BS!D44 -> 764 | E15: =BS!E44 -> 807 | F15: =BS!F44 -> 959 | G15: =G35*IS!G$2/365 -> 865.80652 | H15: =H35*IS!H$2/365 -> 937.27979 | I15: =I35*IS!I$2/365 -> 1018.8469 | J15: =J35*IS!J$2/365 -> 1117.3205 | K15: =K35*IS!K$2/365 -> 1229.7205 | M15: Net Long Term Assets | N15: =SUM(N16:N18) -> 34046 | O15: =SUM(O16:O18) -> 34076 | P15: =SUM(P16:P18) -> 35212 | Q15: =SUM(Q16:Q18) -> 36278 | R15: =SUM(R16:R18) -> 36868 | S15: =S7-S11 -> 37405.006 | T15: =T7-T11 -> 37846.584 | U15: =U7-U11 -> 38284.475 | V15: =V7-V11 -> 38716.277 | W15: =W7-W11 -> 39150.779 | Y15: Interest on taxes and others | Z15: 4 | AA15: 2 | AB15: ₹ - | AC15: 171 | AD15: 215 | AE15: =AD15 -> 215 | AF15: =AE15 -> 215 | AG15: =AF15 -> 215 | AH15: =AG15 -> 215 | AI15: =AH15 -> 215
A16: Provisions (current) | B16: =BS!B45 -> 507 | C16: =BS!C45 -> 346 | D16: =BS!D45 -> 389 | E16: =BS!E45 -> 340 | F16: =BS!F45 -> 675 | G16: =G36*IS!G$2/365 -> 524.35366 | H16: =H36*IS!H$2/365 -> 522.56671 | I16: =I36*IS!I$2/365 -> 575.17836 | J16: =J36*IS!J$2/365 -> 642.20229 | K16: =K36*IS!K$2/365 -> 742.53088 | M16: Owned | N16: =N8-N12 -> 5067 | O16: =O8-O12 -> 5101 | P16: =P8-P12 -> 5767 | Q16: =Q8-Q12 -> 6517 | R16: =R8-R12 -> 6941 | S16: =S8-S12 -> 6417.4909 | T16: =T8-T12 -> 5837.7204 | U16: =U8-U12 -> 5225.2424 | ... W16: =W8-W12 -> 3894.6596 | Y16: Total Interest | Z16: =SUM(Z10:Z15) -> 117 | AA16: =SUM(AA10:AA15) -> 106 | AB16: =SUM(AB10:AB15) -> 114 | AC16: =SUM(AC10:AC15) -> 334 | AD16: =SUM(AD10:AD15) -> 395 | AE16: =SUM(AE10:AE15) -> 398.85549 | AF16: =SUM(AF10:AF15) -> 402.71099 | AG16: =SUM(AG10:AG15) -> 406.56648 | ... AI16: =SUM(AI10:AI15) -> 414.27747
A17: Current Tax Liabilities | B17: =BS!B46 -> 0 | C17: =BS!C46 -> 0 | D17: =BS!D46 -> 0 | E17: =BS!E46 -> 0 | F17: =BS!F46 -> 1903 | G17: =G37*IS!G$2/365 -> 0 | H17: =H37*IS!H$2/365 -> 192.43362 | I17: =I37*IS!I$2/365 -> 414.20475 | J17: =J37*IS!J$2/365 -> 672.70569 | K17: =K37*IS!K$2/365 -> 978.37724 | M17: Leased(Right of Use Assets) | N17: =N9-N13 -> 1049 | O17: =O9-O13 -> 1068 | P17: =P9-P13 -> 1182 | Q17: =Q9-Q13 -> 1514 | R17: =R9-R13 -> 1684 | S17: =S9-S13 -> 1562.5601 | T17: =T9-T13 -> 1427.8119 | U17: =U9-U13 -> 1285.4138 | ... W17: =W9-W13 -> 975.91737
A18: Net Working Capital | B18: =SUM(B3:B10)-SUM(B12:B17) -> 1550 | C18: =SUM(C3:C10)-SUM(C12:C17) -> 3397 | D18: =SUM(D3:D10)-SUM(D12:D17) -> 4668 | E18: =SUM(E3:E10)-SUM(E12:E17) -> 8001 | F18: =SUM(F3:F10)-SUM(F12:F17) -> -152 | G18: =SUM(G3:G10)-SUM(G12:G17) -> 4302.3311 | H18: =SUM(H3:H10)-SUM(H12:H17) -> 5005.8772 | I18: =SUM(I3:I10)-SUM(I12:I17) -> 5352.5716 | ... K18: =SUM(K3:K10)-SUM(K12:K17) -> 6120.8693 | M18: Other intangible assets | N18: =N10-N14 -> 27930 | O18: =O10-O14 -> 27907 | P18: =P10-P14 -> 28263 | Q18: =Q10-Q14 -> 28247 | R18: =R10-R14 -> 28243 | S18: =S10-S14 -> 29424.955 | T18: =T10-T14 -> 30581.052 | U18: =U10-U14 -> 31773.819 | ... W18: =W10-W14 -> 34280.202 | Y18: Cost of Borrowing (%) | AA18: 0 | AB18: 0 | AC18: 0 | AD18: 0 | AE18: 0 | AF18: 0 | AG18: 0 | AH18: 0 | AI18: 0
A19: Changes in NWC | C19: =C18-B18 -> 1847 | D19: =D18-C18 -> 1271 | E19: =E18-D18 -> 3333 | F19: =F18-E18 -> -8153 | G19: =G18-F18 -> 4454.3311 | H19: =H18-G18 -> 703.54614 | I19: =I18-H18 -> 346.69432 | J19: =J18-I18 -> 425.01257 | K19: =K18-J18 -> 343.28522 | M19: Depreciation and amortisation expense | N19: =IS!B10 -> 1074 | O19: =IS!C10 -> 1091 | P19: =IS!D10 -> 1137 | Q19: =IS!E10 -> 1216 | R19: =IS!F10 -> 1355 | S19: =S7*S20 -> 1317.9938 | T19: =T7*T20 -> 1376.4159 | U19: =U7*U20 -> 1438.5245 | V19: =V7*V20 -> 1506.723 | W19: =W7*W20 -> 1572.2208 | Y19: Cost Of Lease (%) | AA19: =AA14/AA8 -> 0.076701822 | AB19: =AB14/AB8 -> 0.074933095 | AC19: =AC14/AC8 -> 0.072059823 | AD19: =AD14/AD8 -> 0.077109897 | AE19: =AD19 -> 0.077109897 | AF19: =AE19 -> 0.077109897 | AG19: =AF19 -> 0.077109897 | AH19: =AG19 -> 0.077109897 | AI19: =AH19 -> 0.077109897
M20: As a % of Opening GLTA | N20: =N19/N7 -> 0.028619394 | O20: =O19/O7 -> 0.028574422 | P20: =P19/P7 -> 0.028355529 | Q20: =Q19/Q7 -> 0.029103442 | R20: =R19/R7 -> 0.031294748 | S20: =AVERAGE(N20:R20) -> 0.029189507 | T20: =AVERAGE(O20:S20) -> 0.029303529 | U20: =AVERAGE(P20:T20) -> 0.029449351 | V20: =AVERAGE(Q20:U20) -> 0.029668115 | W20: =AVERAGE(R20:V20) -> 0.02978105 | Y20: Weighted Average Cost Of Borrowing | AA20: =AA16/(AA8+AA4) -> 0.10162991 | AB20: =AB16/(AB8+AB4) -> 0.093519278 | AC20: =AC16/(AC8+AC4) -> 0.22506739 | AD20: =AD16/(AD8+AD4) -> 0.23968447 | AE20: =AE16/(AE8+AE4) -> 0.23503565 | AF20: =AF16/(AF8+AF4) -> 0.23051574 | AG20: =AG16/(AG8+AG4) -> 0.22624735 | AH20: =AH16/(AH8+AH4) -> 0.22221006 | AI20: =AI16/(AI8+AI4) -> 0.2183856
A21: Current Assets as days of sales: | Y21: Net Borrowing Raised | Z21: 0 | AA21: =AA4-Z4 -> 0 | AB21: =AB4-AA4 -> 98 | AC21: =AC4-AB4 -> -85 | AD21: =AD4-AC4 -> -12 | AE21: 0 | AF21: 0 | AG21: 0 | AH21: 0 | AI21: 0
A22: Inventories | B22: =B3/IS!B$2*365 -> 27.777813 | C22: =C3/IS!C$2*365 -> 28.495407 | D22: =D3/IS!D$2*365 -> 25.612661 | E22: =E3/IS!E$2*365 -> 23.717688 | F22: =F3/IS!F$2*365 -> 25.529935 | G22: =AVERAGE(B22:F22) -> 26.226701 | H22: =AVERAGE(C22:G22) -> 25.916478 | I22: =AVERAGE(D22:H22) -> 25.400692 | J22: =AVERAGE(E22:I22) -> 25.358299 | K22: =AVERAGE(F22:J22) -> 25.686421 | M22: Total Capex | O22: =O23+O24 -> 1728 | P22: =P23+P24 -> 3008 | Q22: =Q23+Q24 -> 2821 | R22: =R23+R24 -> 2732 | S22: =S23+S24 -> 1855 | T22: =T23+T24 -> 1817.9938 | U22: =U23+U24 -> 1876.4159 | V22: =V23+V24 -> 1938.5245 | W22: =W23+W24 -> 2006.723 | Y22: Net Lease added | AA22: =AA8-Z8 -> 34 | AB22: =AB8-AA8 -> 78 | AC22: =AC8-AB8 -> 350 | AD22: =AD8-AC8 -> 176 | AE22: 50 | AF22: 50 | AG22: 50 | AH22: 50 | AI22: 50
A23: Investments | B23: =B4/IS!B$2*365 -> 21.00993 | C23: =C4/IS!C$2*365 -> 24.481283 | D23: =D4/IS!D$2*365 -> 16.93653 | E23: =E4/IS!E$2*365 -> 26.878474 | F23: =F4/IS!F$2*365 -> 21.690325 | G23: =AVERAGE(B23:F23) -> 22.199308 | H23: =AVERAGE(C23:G23) -> 22.437184 | I23: =AVERAGE(D23:H23) -> 22.028364 | J23: =AVERAGE(E23:I23) -> 23.046731 | K23: =AVERAGE(F23:J23) -> 22.280383 | M23: Maintenance Capex | O23: =N19 -> 1074 | P23: =O19 -> 1091 | Q23: =P19 -> 1137 | R23: =Q19 -> 1216 | S23: =R19 -> 1355 | T23: =S19 -> 1317.9938 | U23: =T19 -> 1376.4159 | V23: =U19 -> 1438.5245 | W23: =V19 -> 1506.723
A24: Trade receivables | B24: =B5/IS!B$2*365 -> 13.644425 | C24: =C5/IS!C$2*365 -> 15.555598 | D24: =D5/IS!D$2*365 -> 18.551255 | E24: =E5/IS!E$2*365 -> 17.673275 | F24: =F5/IS!F$2*365 -> 22.083538 | G24: =AVERAGE(B24:F24) -> 17.501618 | H24: =AVERAGE(C24:G24) -> 18.273057 | I24: =AVERAGE(D24:H24) -> 18.816548 | J24: =AVERAGE(E24:I24) -> 18.869607 | K24: =AVERAGE(F24:J24) -> 19.108874 | M24: Growth Capex | O24: =O7-N7 -> 654 | P24: =P7-O7 -> 1917 | Q24: =Q7-P7 -> 1684 | R24: =R7-Q7 -> 1516 | S24: 500 | T24: 500 | U24: 500 | V24: 500 | W24: 500
A25: Bank balances other than cash equivalents | B25: =B6/IS!B$2*365 -> 20.404546 | C25: =C6/IS!C$2*365 -> 18.776636 | D25: =D6/IS!D$2*365 -> 23.88346 | E25: =E6/IS!E$2*365 -> 39.710321 | F25: =F6/IS!F$2*365 -> 8.5755137 | G25: 22 | H25: 23 | I25: 24 | J25: 25 | K25: 26
A26: Loans | B26: =B7/IS!B$2*365 -> 0.26388534 | C26: =C7/IS!C$2*365 -> 0.24349102 | D26: =D7/IS!D$2*365 -> 0.21690327 | E26: =E7/IS!E$2*365 -> 0.22408556 | F26: =F7/IS!F$2*365 -> 0.26599705 | G26: =AVERAGE(B26:F26) -> 0.24287245 | H26: =AVERAGE(C26:G26) -> 0.23866987 | I26: =AVERAGE(D26:H26) -> 0.23770564 | J26: =AVERAGE(E26:I26) -> 0.24186612 | K26: =AVERAGE(F26:J26) -> 0.24542223
A27: Other financial assets (current) | B27: =B8/IS!B$2*365 -> 8.9565791 | C27: =C8/IS!C$2*365 -> 7.5760493 | D27: =D8/IS!D$2*365 -> 8.3507758 | E27: =E8/IS!E$2*365 -> 8.4032086 | F27: =F8/IS!F$2*365 -> 8.6044264 | G27: =AVERAGE(B27:F27) -> 8.3782078 | H27: =AVERAGE(C27:G27) -> 8.2625336 | I27: =AVERAGE(D27:H27) -> 8.3998305 | J27: =AVERAGE(E27:I27) -> 8.4096414 | K27: =AVERAGE(F27:J27) -> 8.4109279
A28: Other current assets | B28: =B9/IS!B$2*365 -> 3.8573828 | C28: =C9/IS!C$2*365 -> 4.7863378 | D28: =D9/IS!D$2*365 -> 4.4886926 | E28: =E9/IS!E$2*365 -> 4.2045528 | F28: =F9/IS!F$2*365 -> 5.5223301 | G28: =AVERAGE(B28:F28) -> 4.5718592 | H28: =AVERAGE(C28:G28) -> 4.7147545 | I28: =AVERAGE(D28:H28) -> 4.7004379 | J28: =AVERAGE(E28:I28) -> 4.7427869 | K28: =AVERAGE(F28:J28) -> 4.8504337
A29: Assets held for sale | B29: =B10/IS!B$2*365 -> 0.13194267 | C29: =C10/IS!C$2*365 -> 0.090439523 | D29: =D10/IS!D$2*365 -> 0.072301089 | E29: =E10/IS!E$2*365 -> 0.070763862 | F29: =F10/IS!F$2*365 -> 0.13299853 | G29: =AVERAGE(B29:F29) -> 0.099689135 | H29: =AVERAGE(C29:G29) -> 0.093238427 | I29: =AVERAGE(D29:H29) -> 0.093798208 | J29: =AVERAGE(E29:I29) -> 0.098097632 | K29: =AVERAGE(F29:J29) -> 0.10356439
A31: Current Liabilities as days of sales:
A32: Trade payables - micro & small enterprises | B32: =B12/IS!B$2*365 -> 0.52000936 | C32: =C12/IS!C$2*365 -> 0.41741318 | D32: =D12/IS!D$2*365 -> 0.60250908 | E32: =E12/IS!E$2*365 -> 1.4742471 | F32: =F12/IS!F$2*365 -> 1.5208092 | G32: =AVERAGE(B32:F32) -> 0.9069976 | H32: =AVERAGE(C32:G32) -> 0.98439524 | I32: =AVERAGE(D32:H32) -> 1.0977917 | J32: =AVERAGE(E32:I32) -> 1.1968482 | K32: =AVERAGE(F32:J32) -> 1.1413684
A33: Trade payables - others | B33: =B13/IS!B$2*365 -> 67.79525 | C33: =C13/IS!C$2*365 -> 62.667632 | D33: =D13/IS!D$2*365 -> 57.08171 | E33: =E13/IS!E$2*365 -> 60.361574 | F33: =F13/IS!F$2*365 -> 63.908683 | G33: =AVERAGE(B33:F33) -> 62.36297 | H33: =AVERAGE(C33:G33) -> 61.276514 | I33: =AVERAGE(D33:H33) -> 60.99829 | J33: =AVERAGE(E33:I33) -> 61.781606 | K33: =AVERAGE(F33:J33) -> 62.065613
A34: Other financial liabilities | B34: =B14/IS!B$2*365 -> 7.2025176 | C34: =C14/IS!C$2*365 -> 6.2542408 | D34: =D14/IS!D$2*365 -> 5.3563057 | E34: =E14/IS!E$2*365 -> 5.100895 | F34: =F14/IS!F$2*365 -> 7.4016571 | G34: =AVERAGE(B34:F34) -> 6.2631233 | H34: =AVERAGE(C34:G34) -> 6.0752444 | I34: =AVERAGE(D34:H34) -> 6.0394451 | J34: =AVERAGE(E34:I34) -> 6.176073 | K34: =AVERAGE(F34:J34) -> 6.3911086
A35: Other current liabilities | B35: =B15/IS!B$2*365 -> 4.5636642 | C35: =C15/IS!C$2*365 -> 4.6263294 | D35: =D15/IS!D$2*365 -> 4.6031694 | E35: =E15/IS!E$2*365 -> 4.7588697 | F35: =F15/IS!F$2*365 -> 5.5454603 | G35: =AVERAGE(B35:F35) -> 4.8194986 | H35: =AVERAGE(C35:G35) -> 4.8706655 | I35: =AVERAGE(D35:H35) -> 4.9195327 | J35: =AVERAGE(E35:I35) -> 4.9828054 | K35: =AVERAGE(F35:J35) -> 5.0275925
A36: Provisions (current) | B36: =B16/IS!B$2*365 -> 3.9349962 | C36: =C16/IS!C$2*365 -> 2.4070827 | D36: =D16/IS!D$2*365 -> 2.3437603 | E36: =E16/IS!E$2*365 -> 2.0049761 | F36: =F16/IS!F$2*365 -> 3.9032176 | G36: =AVERAGE(B36:F36) -> 2.9188066 | H36: =AVERAGE(C36:G36) -> 2.7155687 | I36: =AVERAGE(D36:H36) -> 2.7772659 | J36: =AVERAGE(E36:I36) -> 2.863967 | K36: =AVERAGE(F36:J36) -> 3.0357651
A37: Current Tax Liabilities | B37: =B17/IS!B$2*365 -> 0 | C37: =C17/IS!C$2*365 -> 0 | D37: =D17/IS!D$2*365 -> 0 | E37: =E17/IS!E$2*365 -> 0 | F37: =F17/IS!F$2*365 -> 11.004182 | G37: 0 | H37: 1 | I37: 2 | J37: 3 | K37: 4

Sheet Assumption
A1: Particulars | B1: 2021 | C1: =B1+1 -> 2022 | D1: =C1+1 -> 2023 | E1: =D1+1 -> 2024 | F1: =E1+1 -> 2025 | G1: =F1+1 -> 2026 | H1: =G1+1 -> 2027 | I1: =H1+1 -> 2028 | J1: =I1+1 -> 2029 | K1: =J1+1 -> 2030
A2: Revenue from operations | B2: =IS!B2 -> 47028 | C2: =IS!C2 -> 52466 | D2: =IS!D2 -> 60580 | E2: =IS!E2 -> 61896 | F2: =IS!F2 -> 63121 | G2: =G25 -> 65571.007 | H2: =H25 -> 70238.271 | I2: =I25 -> 75592.367 | J2: =J25 -> 81845.858 | K2: =K25 -> 89276.923
A3: Other income | B3: =IS!B3 -> 410 | C3: =IS!C3 -> 258 | D3: =IS!D3 -> 512 | E3: =IS!E3 -> 811 | F3: =IS!F3 -> 1017 | G3: =G27 -> 1118.7 | H3: =H27 -> 1241.757 | I3: =I27 -> 1390.7678 | J3: =J27 -> 1571.5677 | K3: =K27 -> 1791.5871
A4: Cost of materials consumed | B4: =IS!B5 -> 15432 | C4: =IS!C5 -> 16446 | D4: =IS!D5 -> 20212 | E4: =IS!E5 -> 19257 | F4: =IS!F5 -> 19458 | G4: =G31 -> 20912.303 | H4: =H31 -> 22271.311 | I4: =I31 -> 24023.761 | J4: =J31 -> 25751.961 | K4: =K31 -> 28152.94
A5: Purchases of stock-in-trade | B5: =IS!B6 -> 7121 | C5: =IS!C6 -> 9311 | D5: =IS!D6 -> 11579 | E5: =IS!E6 -> 10514 | F5: =IS!F6 -> 11272 | G5: =G34 -> 11389.247 | H5: =H34 -> 12512.801 | I5: =I34 -> 13476.912 | J5: =J34 -> 14381.439 | K5: =K34 -> 15791.599
A6: Changes in inventories of FG and WIP | B6: =IS!B7 -> -405 | C6: =IS!C7 -> -22 | D6: =IS!D7 -> -75 | E6: =IS!E7 -> -11 | F6: =IS!F7 -> -153 | G6: =0 -> 0 | H6: =0 -> 0 | I6: =0 -> 0 | J6: =0 -> 0 | K6: =0 -> 0
A7: Employee benefits expenses | B7: =IS!B8 -> 2358 | C7: =IS!C8 -> 2545 | D7: =IS!D8 -> 2854 | E7: =IS!E8 -> 3009 | F7: =IS!F8 -> 3077 | G7: =G37 -> 3457.3172 | H7: =H37 -> 3939.7858 | I7: =I37 -> 4552.8165 | J7: =J37 -> 5334.7627 | K7: =K37 -> 6337.6981
A8: Other expenses | B8: =IS!B11 -> 10896 | C8: =IS!C11 -> 11309 | D8: =IS!D11 -> 11861 | E8: =IS!E11 -> 14464 | F8: =IS!F11 -> 14615 | G8: =G43 -> 14440.372 | H8: =H43 -> 15307.139 | I8: =I43 -> 16509.985 | J8: =J43 -> 18245.756 | K8: =K43 -> 19710.333
A9: Share of equity accounted investee and tax | B9: =IS!B14 -> 0 | C9: =IS!C14 -> 0 | D9: =IS!D14 -> -1 | E9: =IS!E14 -> -4 | F9: =IS!F14 -> -8 | G9: 0 | H9: 0 | I9: 0 | J9: 0 | K9: 0
A10: Exceptional items (net) | B10: =IS!B16 -> -239 | C10: =IS!C16 -> -44 | D10: =IS!D16 -> -64 | E10: =IS!E16 -> 6 | F10: =IS!F16 -> 305 | G10: =F10 -> 305 | H10: =G10 -> 305 | I10: =H10 -> 305 | J10: =I10 -> 305 | K10: =J10 -> 305
A11: Tax | B11: =B12+B13 -> -2606 | C11: =C12+C13 -> -2987 | D11: =D12+D13 -> -3201 | E11: =E12+E13 -> -3644 | F11: =F12+F13 -> -3744 | G11: =G66 -> -3769.6547 | H11: =H66 -> -3993.716 | I11: =I66 -> -4219.8923 | J11: =J66 -> -4522.8407 | K11: =K66 -> -4848.6104
A12: Current tax | B12: =IS!B18 -> -2520 | C12: =IS!C18 -> -2840 | D12: =IS!D18 -> -3001 | E12: =IS!E18 -> -3521 | F12: =IS!F18 -> -3620 | G12: =G68 -> -3644.8051 | H12: =H68 -> -3861.4455 | I12: =I68 -> -4080.1309 | J12: =J68 -> -4373.0458 | K12: =K68 -> -4688.0261
A13: Deferred tax charge | B13: =IS!B19 -> -86 | C13: =IS!C19 -> -147 | D13: =IS!D19 -> -200 | E13: =IS!E19 -> -123 | F13: =IS!F19 -> -124 | G13: =G70 -> -124.84968 | H13: =H70 -> -132.27051 | I13: =I70 -> -139.76139 | J13: =J70 -> -149.79494 | K13: =K70 -> -160.58432
A16: Revenue Model | B16: 2021 | C16: =B16+1 -> 2022 | D16: =C16+1 -> 2023 | E16: =D16+1 -> 2024 | F16: =E16+1 -> 2025 | G16: =F16+1 -> 2026 | H16: =G16+1 -> 2027 | I16: =H16+1 -> 2028 | J16: =I16+1 -> 2029 | K16: =J16+1 -> 2030
A17: Home Care | B17: 13957 | C17: 16570 | D17: 21223 | E17: 21882 | F17: 22972 | G17: =F17*(1+G18) -> 25269.2 | H17: =G17*(1+H18) -> 27922.466 | I17: =H17*(1+I18) -> 30993.937 | J17: =I17*(1+J18) -> 34558.24 | K17: =J17*(1+K18) -> 38705.229
A18: Growth % | C18: =C17/B17-1 -> 0.18721788 | D18: =D17/C17-1 -> 0.28080869 | E18: =E17/D17-1 -> 0.031051218 | F18: =F17/E17-1 -> 0.049812631 | G18: 0.1 | H18: =G18+0.5% -> 0.105 | I18: =H18+0.5% -> 0.11 | J18: =I18+0.5% -> 0.115 | K18: =J18+0.5% -> 0.12
A19: Beauty and Personal Care | B19: 18038 | C19: 19567 | D19: 22022 | E19: 22448 | F19: 22241 | G19: =F19*(1+G20) -> 23353.05 | H19: =G19*(1+H20) -> 24754.233 | I19: =H19*(1+I20) -> 26487.029 | J19: =I19*(1+J20) -> 28605.992 | K19: =J19*(1+K20) -> 31180.531
A20: Growth % | C20: =C19/B19-1 -> 0.084765495 | D20: =D19/C19-1 -> 0.12546635 | E20: =E19/D19-1 -> 0.019344292 | F20: =F19/E19-1 -> -0.0092213115 | G20: 0.05 | H20: =G20+1% -> 0.06 | I20: =H20+1% -> 0.07 | J20: =I20+1% -> 0.08 | K20: =J20+1% -> 0.09
A21: Foods and Refreshment | B21: 13204 | C21: 14105 | D21: 14876 | E21: 15291 | F21: 15294 | G21: =F21*(1+G22) -> 15871.317 | H21: =G21*(1+H22) -> 16349.452 | I21: =H21*(1+I22) -> 16741.705 | J21: =I21*(1+J22) -> 17127.022 | K21: =J21*(1+K22) -> 17618.914
A22: Growth % | C22: =C21/B21-1 -> 0.068236898 | D22: =D21/C21-1 -> 0.054661468 | E22: =E21/D21-1 -> 0.027897284 | F22: =F21/E21-1 -> 0.00019619384 | G22: =AVERAGE(C22:F22) -> 0.037747961 | H22: =AVERAGE(D22:G22) -> 0.030125727 | I22: =AVERAGE(E22:H22) -> 0.023991791 | J22: =AVERAGE(F22:I22) -> 0.023015418 | K22: =AVERAGE(G22:J22) -> 0.028720224
A23: Others(Includes Exports, Consigments, etc.) | B23: 1829 | C23: 2204 | D23: 2459 | E23: 2275 | F23: 962 | G23: =F23*(1+G24) -> 1077.44 | H23: =G23*(1+H24) -> 1212.12 | I23: =H23*(1+I24) -> 1369.6956 | J23: =I23*(1+J24) -> 1554.6045 | K23: =J23*(1+K24) -> 1772.2491
A24: Growth % | C24: =C23/B23-1 -> 0.20503007 | D24: =D23/C23-1 -> 0.11569873 | E24: =E23/D23-1 -> -0.074827166 | F24: =F23/E23-1 -> -0.57714286 | G24: 0.12 | H24: =G24+0.5% -> 0.125 | I24: =H24+0.5% -> 0.13 | J24: =I24+0.5% -> 0.135 | K24: =J24+0.5% -> 0.14
A25: Revenue | B25: =B17+B19+B21+B23 -> 47028 | C25: =C17+C19+C21+C23 -> 52446 | D25: =D17+D19+D21+D23 -> 60580 | E25: =E17+E19+E21+E23 -> 61896 | F25: =F17+F19+F21+F23 -> 61469 | G25: =G17+G19+G21+G23 -> 65571.007 | H25: =H17+H19+H21+H23 -> 70238.271 | I25: =I17+I19+I21+I23 -> 75592.367 | ... K25: =K17+K19+K21+K23 -> 89276.923
A26: Growth % | C26: =C25/B25-1 -> 0.11520796 | D26: =D25/C25-1 -> 0.15509286 | E26: =E25/D25-1 -> 0.021723341 | F26: =F25/E25-1 -> -0.0068986687 | G26: =G25/F25-1 -> 0.066732944 | H26: =H25/G25-1 -> 0.071178775 | I26: =I25/H25-1 -> 0.076227614 | J26: =J25/I25-1 -> 0.082726492 | K26: =K25/J25-1 -> 0.09079341
A27: Other income | B27: =B3 -> 410 | C27: =C3 -> 258 | D27: =D3 -> 512 | E27: =E3 -> 811 | F27: =F3 -> 1017 | G27: =F27*(1+G28) -> 1118.7 | H27: =G27*(1+H28) -> 1241.757 | I27: =H27*(1+I28) -> 1390.7678 | J27: =I27*(1+J28) -> 1571.5677 | K27: =J27*(1+K28) -> 1791.5871
C28: =C27/B27-1 -> -0.37073171 | D28: =D27/C27-1 -> 0.98449612 | E28: =E27/D27-1 -> 0.58398438 | F28: =F27/E27-1 -> 0.2540074 | G28: =10% -> 0.1 | H28: =G28+1% -> 0.11 | I28: =H28+1% -> 0.12 | J28: =I28+1% -> 0.13 | K28: =J28+1% -> 0.14
A30: Cost Drivers | B30: 2021 | C30: =B30+1 -> 2022 | D30: =C30+1 -> 2023 | E30: =D30+1 -> 2024 | F30: =E30+1 -> 2025 | G30: =F30+1 -> 2026 | H30: =G30+1 -> 2027 | I30: =H30+1 -> 2028 | J30: =I30+1 -> 2029 | K30: =J30+1 -> 2030
A31: Cost of materials consumed | B31: =B4 -> 15432 | C31: =C4 -> 16446 | D31: =D4 -> 20212 | E31: =E4 -> 19257 | F31: =F4 -> 19458 | G31: =G32*G$2 -> 20912.303 | H31: =H32*H$2 -> 22271.311 | I31: =I32*I$2 -> 24023.761 | J31: =J32*J$2 -> 25751.961 | K31: =K32*K$2 -> 28152.94
A32: As % of Revenue | B32: =B31/B$2 -> 0.32814493 | C32: =C31/C$2 -> 0.31346015 | D32: =D31/D$2 -> 0.33364147 | E32: =E31/E$2 -> 0.31111865 | F32: =F31/F$2 -> 0.30826508 | G32: =AVERAGE(B32:F32) -> 0.31892606 | H32: =AVERAGE(C32:G32) -> 0.31708228 | I32: =AVERAGE(D32:H32) -> 0.31780671 | J32: =AVERAGE(E32:I32) -> 0.31463975 | K32: =AVERAGE(F32:J32) -> 0.31534397
A34: Purchases of stock-in-trade | B34: =B5 -> 7121 | C34: =C5 -> 9311 | D34: =D5 -> 11579 | E34: =E5 -> 10514 | F34: =F5 -> 11272 | G34: =G35*G$2 -> 11389.247 | H34: =H35*H$2 -> 12512.801 | I34: =I35*I$2 -> 13476.912 | J34: =J35*J$2 -> 14381.439 | K34: =K35*K$2 -> 15791.599
A35: As % of Revenue | B35: =B34/B$2 -> 0.15142043 | C35: =C34/C$2 -> 0.17746731 | D35: =D34/D$2 -> 0.19113569 | E35: =E34/E$2 -> 0.16986558 | F35: =F34/F$2 -> 0.17857765 | G35: =AVERAGE(B35:F35) -> 0.17369333 | H35: =AVERAGE(C35:G35) -> 0.17814791 | I35: =AVERAGE(D35:H35) -> 0.17828403 | J35: =AVERAGE(E35:I35) -> 0.1757137 | K35: =AVERAGE(F35:J35) -> 0.17688333
A37: Employee benefits expenses | B37: =B7 -> 2358 | C37: =C7 -> 2545 | D37: =D7 -> 2854 | E37: =E7 -> 3009 | F37: =F7 -> 3077 | G37: =G38*G40 -> 3457.3172 | H37: =H38*H40 -> 3939.7858 | I37: =I38*I40 -> 4552.8165 | J37: =J38*J40 -> 5334.7627 | K37: =K38*K40 -> 6337.6981
A38: No. of Employee | B38: 8525 | C38: 8480 | D38: 6697 | E38: 7215 | F38: 8202 | G38: =F38*(1+G39) -> 8694.12 | H38: =G38*(1+H39) -> 9302.7084 | I38: =H38*(1+I39) -> 10046.925 | J38: =I38*(1+J39) -> 10951.148 | K38: =J38*(1+K39) -> 12046.263
A39: Growth % | C39: =C38/B38-1 -> -0.0052785924 | D39: =D38/C38-1 -> -0.21025943 | E39: =E38/D38-1 -> 0.077348066 | F39: =F38/E38-1 -> 0.13679834 | G39: =6% -> 0.06 | H39: =G39+1% -> 0.07 | I39: =H39+1% -> 0.08 | J39: =I39+1% -> 0.09 | K39: =J39+1% -> 0.1
A40: Revenue Per employee(in cr) | B40: =B37/B38 -> 0.27659824 | C40: =C37/C38 -> 0.30011792 | D40: =D37/D38 -> 0.42616097 | E40: =E37/E38 -> 0.41704782 | F40: =F37/F38 -> 0.3751524 | G40: =F40*(1+G41) -> 0.39766155 | H40: =G40*(1+H41) -> 0.42350955 | I40: =H40*(1+I41) -> 0.45315521 | J40: =I40*(1+J41) -> 0.48714186 | K40: =J40*(1+K41) -> 0.5261132
A41: Growth % | C41: =C40/B40-1 -> 0.085031937 | D41: =D40/C40-1 -> 0.41997839 | E41: =E40/D40-1 -> -0.021384292 | F41: =F40/E40-1 -> -0.1004571 | G41: =6% -> 0.06 | H41: =G41+0.5% -> 0.065 | I41: =H41+0.5% -> 0.07 | J41: =I41+0.5% -> 0.075 | K41: =J41+0.5% -> 0.08
A43: Other expenses | B43: =B8 -> 10896 | C43: =C8 -> 11309 | D43: =D8 -> 11861 | E43: =E8 -> 14464 | F43: =F8 -> 14615 | G43: =SUM(G44,G46,G48,G50,G52,G54,G56,G58,G60,G62,G64) -> 14440.372 | H43: =SUM(H44,H46,H48,H50,H52,H54,H56,H58,H60,H62,H64) -> 15307.139 | I43: =SUM(I44,I46,I48,I50,I52,I54,I56,I58,I60,I62,I64) -> 16509.985 | J43: =SUM(J44,J46,J48,J50,J52,J54,J56,J58,J60,J62,J64) -> 18245.756 | K43: =SUM(K44,K46,K48,K50,K52,K54,K56,K58,K60,K62,K64) -> 19710.333
A44: Adverstising & Promotion | B44: 4754 | C44: 4744 | D44: 4907 | E44: 6489 | F44: 6028 | G44: =G45*G$2 -> 6200.9947 | H44: =H45*H$2 -> 6550.7894 | I44: =I45*I$2 -> 7093.1492 | J44: =J45*J$2 -> 7890.0204 | K44: =K45*K$2 -> 8455.7511
A45: As % of Revenue | B45: =B44/B$2 -> 0.10108871 | C45: =C44/C$2 -> 0.090420463 | D45: =D44/D$2 -> 0.08100033 | E45: =E44/E$2 -> 0.10483715 | F45: =F44/F$2 -> 0.095499121 | G45: =AVERAGE(B45:F45) -> 0.094569155 | H45: =AVERAGE(C45:G45) -> 0.093265243 | I45: =AVERAGE(D45:H45) -> 0.093834199 | J45: =AVERAGE(E45:I45) -> 0.096400973 | K45: =AVERAGE(F45:J45) -> 0.094713738
A46: Carriage & Freight | B46: 1743 | C46: 1874 | D46: 1972 | E46: 2005 | F46: 1958 | G46: =G47*G$2 -> 2212.972 | H46: =H47*H$2 -> 2323.9378 | I46: =I47*I$2 -> 2461.296 | J46: =J47*J$2 -> 2665.0433 | K46: =K47*K$2 -> 2910.0237
...
